{
    "GSD": {
        "alias": "CVE-2010-3494",
        "description": "Race condition in the FTPHandler class in ftpserver.py in pyftpdlib before 0.5.2 allows remote attackers to cause a denial of service (daemon outage) by establishing and then immediately closing a TCP connection, leading to the accept function having an unexpected value of None for the address, or an ECONNABORTED, EAGAIN, or EWOULDBLOCK error, a related issue to CVE-2010-3492.",
        "id": "GSD-2010-3494"
    },
    "namespaces": {
        "cve.org": {
            "CVE_data_meta": {
                "ASSIGNER": "cve@mitre.org",
                "ID": "CVE-2010-3494",
                "STATE": "PUBLIC"
            },
            "affects": {
                "vendor": {
                    "vendor_data": [
                        {
                            "product": {
                                "product_data": [
                                    {
                                        "product_name": "n/a",
                                        "version": {
                                            "version_data": [
                                                {
                                                    "version_value": "n/a"
                                                }
                                            ]
                                        }
                                    }
                                ]
                            },
                            "vendor_name": "n/a"
                        }
                    ]
                }
            },
            "data_format": "MITRE",
            "data_type": "CVE",
            "data_version": "4.0",
            "description": {
                "description_data": [
                    {
                        "lang": "eng",
                        "value": "Race condition in the FTPHandler class in ftpserver.py in pyftpdlib before 0.5.2 allows remote attackers to cause a denial of service (daemon outage) by establishing and then immediately closing a TCP connection, leading to the accept function having an unexpected value of None for the address, or an ECONNABORTED, EAGAIN, or EWOULDBLOCK error, a related issue to CVE-2010-3492."
                    }
                ]
            },
            "problemtype": {
                "problemtype_data": [
                    {
                        "description": [
                            {
                                "lang": "eng",
                                "value": "n/a"
                            }
                        ]
                    }
                ]
            },
            "references": {
                "reference_data": [
                    {
                        "name": "[oss-security] 20100910 Re: CVE Request -- Python -- accept() implementation in async core is broken => more subcases",
                        "refsource": "MLIST",
                        "url": "http://www.openwall.com/lists/oss-security/2010/09/11/2"
                    },
                    {
                        "name": "http://code.google.com/p/pyftpdlib/source/detail?r=556",
                        "refsource": "CONFIRM",
                        "url": "http://code.google.com/p/pyftpdlib/source/detail?r=556"
                    },
                    {
                        "name": "http://code.google.com/p/pyftpdlib/source/browse/trunk/HISTORY",
                        "refsource": "CONFIRM",
                        "url": "http://code.google.com/p/pyftpdlib/source/browse/trunk/HISTORY"
                    },
                    {
                        "name": "https://bugs.launchpad.net/zodb/+bug/135108",
                        "refsource": "MISC",
                        "url": "https://bugs.launchpad.net/zodb/+bug/135108"
                    },
                    {
                        "name": "http://code.google.com/p/pyftpdlib/source/diff?spec=svn556&r=556&format=side&path=/trunk/pyftpdlib/ftpserver.py",
                        "refsource": "CONFIRM",
                        "url": "http://code.google.com/p/pyftpdlib/source/diff?spec=svn556&r=556&format=side&path=/trunk/pyftpdlib/ftpserver.py"
                    },
                    {
                        "name": "http://code.google.com/p/pyftpdlib/issues/detail?id=105",
                        "refsource": "CONFIRM",
                        "url": "http://code.google.com/p/pyftpdlib/issues/detail?id=105"
                    },
                    {
                        "name": "[oss-security] 20100924 Re: CVE Request -- Python -- accept() implementation in async core is broken => more subcases",
                        "refsource": "MLIST",
                        "url": "http://www.openwall.com/lists/oss-security/2010/09/24/3"
                    },
                    {
                        "name": "[oss-security] 20100922 Re: CVE Request -- Python -- accept() implementation in async core is broken => more subcases",
                        "refsource": "MLIST",
                        "url": "http://www.openwall.com/lists/oss-security/2010/09/22/3"
                    },
                    {
                        "name": "http://code.google.com/p/pyftpdlib/issues/detail?id=104",
                        "refsource": "CONFIRM",
                        "url": "http://code.google.com/p/pyftpdlib/issues/detail?id=104"
                    },
                    {
                        "name": "http://bugs.python.org/issue6706",
                        "refsource": "MISC",
                        "url": "http://bugs.python.org/issue6706"
                    },
                    {
                        "name": "[oss-security] 20100909 CVE Request -- Python -- accept() implementation in async core is broken => more subcases",
                        "refsource": "MLIST",
                        "url": "http://www.openwall.com/lists/oss-security/2010/09/09/6"
                    }
                ]
            }
        },
        "nvd.nist.gov": {
            "configurations": {
                "CVE_data_version": "4.0",
                "nodes": [
                    {
                        "children": [],
                        "cpe_match": [
                            {
                                "cpe23Uri": "cpe:2.3:a:g.rodola:pyftpdlib:0.4.0:*:*:*:*:*:*:*",
                                "cpe_name": [],
                                "vulnerable": true
                            },
                            {
                                "cpe23Uri": "cpe:2.3:a:g.rodola:pyftpdlib:*:*:*:*:*:*:*:*",
                                "cpe_name": [],
                                "versionEndIncluding": "0.5.1",
                                "vulnerable": true
                            },
                            {
                                "cpe23Uri": "cpe:2.3:a:g.rodola:pyftpdlib:0.1:*:*:*:*:*:*:*",
                                "cpe_name": [],
                                "vulnerable": true
                            },
                            {
                                "cpe23Uri": "cpe:2.3:a:g.rodola:pyftpdlib:0.1.1:*:*:*:*:*:*:*",
                                "cpe_name": [],
                                "vulnerable": true
                            },
                            {
                                "cpe23Uri": "cpe:2.3:a:g.rodola:pyftpdlib:0.2.0:*:*:*:*:*:*:*",
                                "cpe_name": [],
                                "vulnerable": true
                            },
                            {
                                "cpe23Uri": "cpe:2.3:a:g.rodola:pyftpdlib:0.3.0:*:*:*:*:*:*:*",
                                "cpe_name": [],
                                "vulnerable": true
                            },
                            {
                                "cpe23Uri": "cpe:2.3:a:g.rodola:pyftpdlib:0.5.0:*:*:*:*:*:*:*",
                                "cpe_name": [],
                                "vulnerable": true
                            }
                        ],
                        "operator": "OR"
                    }
                ]
            },
            "cve": {
                "CVE_data_meta": {
                    "ASSIGNER": "cve@mitre.org",
                    "ID": "CVE-2010-3494"
                },
                "data_format": "MITRE",
                "data_type": "CVE",
                "data_version": "4.0",
                "description": {
                    "description_data": [
                        {
                            "lang": "en",
                            "value": "Race condition in the FTPHandler class in ftpserver.py in pyftpdlib before 0.5.2 allows remote attackers to cause a denial of service (daemon outage) by establishing and then immediately closing a TCP connection, leading to the accept function having an unexpected value of None for the address, or an ECONNABORTED, EAGAIN, or EWOULDBLOCK error, a related issue to CVE-2010-3492."
                        }
                    ]
                },
                "problemtype": {
                    "problemtype_data": [
                        {
                            "description": [
                                {
                                    "lang": "en",
                                    "value": "CWE-362"
                                }
                            ]
                        }
                    ]
                },
                "references": {
                    "reference_data": [
                        {
                            "name": "http://code.google.com/p/pyftpdlib/source/diff?spec=svn556&r=556&format=side&path=/trunk/pyftpdlib/ftpserver.py",
                            "refsource": "CONFIRM",
                            "tags": [],
                            "url": "http://code.google.com/p/pyftpdlib/source/diff?spec=svn556&r=556&format=side&path=/trunk/pyftpdlib/ftpserver.py"
                        },
                        {
                            "name": "http://code.google.com/p/pyftpdlib/issues/detail?id=105",
                            "refsource": "CONFIRM",
                            "tags": [],
                            "url": "http://code.google.com/p/pyftpdlib/issues/detail?id=105"
                        },
                        {
                            "name": "http://code.google.com/p/pyftpdlib/source/detail?r=556",
                            "refsource": "CONFIRM",
                            "tags": [],
                            "url": "http://code.google.com/p/pyftpdlib/source/detail?r=556"
                        },
                        {
                            "name": "[oss-security] 20100924 Re: CVE Request -- Python -- accept() implementation in async core is broken => more subcases",
                            "refsource": "MLIST",
                            "tags": [],
                            "url": "http://www.openwall.com/lists/oss-security/2010/09/24/3"
                        },
                        {
                            "name": "https://bugs.launchpad.net/zodb/+bug/135108",
                            "refsource": "MISC",
                            "tags": [],
                            "url": "https://bugs.launchpad.net/zodb/+bug/135108"
                        },
                        {
                            "name": "http://bugs.python.org/issue6706",
                            "refsource": "MISC",
                            "tags": [
                                "Patch"
                            ],
                            "url": "http://bugs.python.org/issue6706"
                        },
                        {
                            "name": "[oss-security] 20100922 Re: CVE Request -- Python -- accept() implementation in async core is broken => more subcases",
                            "refsource": "MLIST",
                            "tags": [],
                            "url": "http://www.openwall.com/lists/oss-security/2010/09/22/3"
                        },
                        {
                            "name": "[oss-security] 20100910 Re: CVE Request -- Python -- accept() implementation in async core is broken => more subcases",
                            "refsource": "MLIST",
                            "tags": [],
                            "url": "http://www.openwall.com/lists/oss-security/2010/09/11/2"
                        },
                        {
                            "name": "[oss-security] 20100909 CVE Request -- Python -- accept() implementation in async core is broken => more subcases",
                            "refsource": "MLIST",
                            "tags": [],
                            "url": "http://www.openwall.com/lists/oss-security/2010/09/09/6"
                        },
                        {
                            "name": "http://code.google.com/p/pyftpdlib/source/browse/trunk/HISTORY",
                            "refsource": "CONFIRM",
                            "tags": [],
                            "url": "http://code.google.com/p/pyftpdlib/source/browse/trunk/HISTORY"
                        },
                        {
                            "name": "http://code.google.com/p/pyftpdlib/issues/detail?id=104",
                            "refsource": "CONFIRM",
                            "tags": [],
                            "url": "http://code.google.com/p/pyftpdlib/issues/detail?id=104"
                        }
                    ]
                }
            },
            "impact": {
                "baseMetricV2": {
                    "cvssV2": {
                        "accessComplexity": "MEDIUM",
                        "accessVector": "NETWORK",
                        "authentication": "NONE",
                        "availabilityImpact": "PARTIAL",
                        "baseScore": 4.3,
                        "confidentialityImpact": "NONE",
                        "integrityImpact": "NONE",
                        "vectorString": "AV:N/AC:M/Au:N/C:N/I:N/A:P",
                        "version": "2.0"
                    },
                    "exploitabilityScore": 8.6,
                    "impactScore": 2.9,
                    "obtainAllPrivilege": false,
                    "obtainOtherPrivilege": false,
                    "obtainUserPrivilege": false,
                    "severity": "MEDIUM",
                    "userInteractionRequired": false
                }
            },
            "lastModifiedDate": "2010-10-20T04:00Z",
            "publishedDate": "2010-10-19T20:00Z"
        }
    }
}